2025-09-15 15:34:14 WARNING app: Could not create default admin user: (psycopg2.errors.UndefinedColumn) column users.grupo_id does not exist
LINE 1: ...sers_nome_completo, users.perfil AS users_perfil, users.grup...
                                                             ^

[SQL: SELECT users.id AS users_id, users.username AS users_username, users.email AS users_email, users.password_hash AS users_password_hash, users.nome_completo AS users_nome_completo, users.perfil AS users_perfil, users.grupo_id AS users_grupo_id, users.cargo AS users_cargo, users.receber_notificacoes AS users_receber_notificacoes, users.ativo AS users_ativo, users.data_criacao AS users_data_criacao, users.ultimo_login AS users_ultimo_login, users.reset_token AS users_reset_token, users.reset_token_expiry AS users_reset_token_expiry 
FROM users 
WHERE users.email = %(email_1)s 
 LIMIT %(param_1)s]
[parameters: {'email_1': 'admin@alphagestao.com', 'param_1': 1}]
(Background on this error at: https://sqlalche.me/e/20/f405) [in /home/runner/workspace/app/__init__.py:144]
 * Serving Flask app 'app'
 * Debug mode: off
2025-09-15 15:34:14 INFO werkzeug: WARNING: This is a development server. Do not use it in a production deployment. Use a production WSGI server instead.
 * Running on all addresses (0.0.0.0)
 * Running on http://127.0.0.1:5000
 * Running on http://172.31.82.130:5000 [in /home/runner/workspace/.pythonlibs/lib/python3.11/site-packages/werkzeug/_internal.py:97]
2025-09-15 15:34:14 INFO werkzeug: Press CTRL+C to quit [in /home/runner/workspace/.pythonlibs/lib/python3.11/site-packages/werkzeug/_internal.py:97]
2025-09-15 15:34:18 ERROR app: Application error: (psycopg2.errors.UndefinedColumn) column users.grupo_id does not exist
LINE 1: ...sers_nome_completo, users.perfil AS users_perfil, users.grup...
                                                             ^

[SQL: SELECT users.id AS users_id, users.username AS users_username, users.email AS users_email, users.password_hash AS users_password_hash, users.nome_completo AS users_nome_completo, users.perfil AS users_perfil, users.grupo_id AS users_grupo_id, users.cargo AS users_cargo, users.receber_notificacoes AS users_receber_notificacoes, users.ativo AS users_ativo, users.data_criacao AS users_data_criacao, users.ultimo_login AS users_ultimo_login, users.reset_token AS users_reset_token, users.reset_token_expiry AS users_reset_token_expiry 
FROM users 
WHERE users.id = %(pk_1)s]
[parameters: {'pk_1': 1}]
(Background on this error at: https://sqlalche.me/e/20/f405) [in /home/runner/workspace/app/__init__.py:86]
Traceback (most recent call last):
  File "/home/runner/workspace/.pythonlibs/lib/python3.11/site-packages/sqlalchemy/engine/base.py", line 1967, in _exec_single_context
    self.dialect.do_execute(
  File "/home/runner/workspace/.pythonlibs/lib/python3.11/site-packages/sqlalchemy/engine/default.py", line 951, in do_execute
    cursor.execute(statement, parameters)
psycopg2.errors.UndefinedColumn: column users.grupo_id does not exist
LINE 1: ...sers_nome_completo, users.perfil AS users_perfil, users.grup...
                                                             ^


The above exception was the direct cause of the following exception:

Traceback (most recent call last):
  File "/home/runner/workspace/.pythonlibs/lib/python3.11/site-packages/flask/app.py", line 917, in full_dispatch_request
    rv = self.dispatch_request()
         ^^^^^^^^^^^^^^^^^^^^^^^
  File "/home/runner/workspace/.pythonlibs/lib/python3.11/site-packages/flask/app.py", line 902, in dispatch_request
    return self.ensure_sync(self.view_functions[rule.endpoint])(**view_args)  # type: ignore[no-any-return]
           ^^^^^^^^^^^^^^^^^^^^^^^^^^^^^^^^^^^^^^^^^^^^^^^^^^^^^^^^^^^^^^^^^
  File "/home/runner/workspace/.pythonlibs/lib/python3.11/site-packages/flask_login/utils.py", line 284, in decorated_view
    elif not current_user.is_authenticated:
             ^^^^^^^^^^^^^^^^^^^^^^^^^^^^^
  File "/home/runner/workspace/.pythonlibs/lib/python3.11/site-packages/werkzeug/local.py", line 318, in __get__
    obj = instance._get_current_object()
          ^^^^^^^^^^^^^^^^^^^^^^^^^^^^^^
  File "/home/runner/workspace/.pythonlibs/lib/python3.11/site-packages/werkzeug/local.py", line 526, in _get_current_object
    return get_name(local())
                    ^^^^^^^
  File "/home/runner/workspace/.pythonlibs/lib/python3.11/site-packages/flask_login/utils.py", line 25, in <lambda>
    current_user = LocalProxy(lambda: _get_user())
                                      ^^^^^^^^^^^
  File "/home/runner/workspace/.pythonlibs/lib/python3.11/site-packages/flask_login/utils.py", line 370, in _get_user
    current_app.login_manager._load_user()
  File "/home/runner/workspace/.pythonlibs/lib/python3.11/site-packages/flask_login/login_manager.py", line 364, in _load_user
    user = self._user_callback(user_id)
           ^^^^^^^^^^^^^^^^^^^^^^^^^^^^
  File "/home/runner/workspace/app/__init__.py", line 155, in load_user
    return User.query.get(int(user_id))
           ^^^^^^^^^^^^^^^^^^^^^^^^^^^^
  File "<string>", line 2, in get
  File "/home/runner/workspace/.pythonlibs/lib/python3.11/site-packages/sqlalchemy/util/deprecations.py", line 386, in warned
    return fn(*args, **kwargs)  # type: ignore[no-any-return]
           ^^^^^^^^^^^^^^^^^^^
  File "/home/runner/workspace/.pythonlibs/lib/python3.11/site-packages/sqlalchemy/orm/query.py", line 1126, in get
    return self._get_impl(ident, loading.load_on_pk_identity)
           ^^^^^^^^^^^^^^^^^^^^^^^^^^^^^^^^^^^^^^^^^^^^^^^^^^
  File "/home/runner/workspace/.pythonlibs/lib/python3.11/site-packages/sqlalchemy/orm/query.py", line 1135, in _get_impl
    return self.session._get_impl(
           ^^^^^^^^^^^^^^^^^^^^^^^
  File "/home/runner/workspace/.pythonlibs/lib/python3.11/site-packages/sqlalchemy/orm/session.py", line 3873, in _get_impl
    return db_load_fn(
           ^^^^^^^^^^^
  File "/home/runner/workspace/.pythonlibs/lib/python3.11/site-packages/sqlalchemy/orm/loading.py", line 695, in load_on_pk_identity
    session.execute(
  File "/home/runner/workspace/.pythonlibs/lib/python3.11/site-packages/sqlalchemy/orm/session.py", line 2365, in execute
    return self._execute_internal(
           ^^^^^^^^^^^^^^^^^^^^^^^
  File "/home/runner/workspace/.pythonlibs/lib/python3.11/site-packages/sqlalchemy/orm/session.py", line 2251, in _execute_internal
    result: Result[Any] = compile_state_cls.orm_execute_statement(
                          ^^^^^^^^^^^^^^^^^^^^^^^^^^^^^^^^^^^^^^^^
  File "/home/runner/workspace/.pythonlibs/lib/python3.11/site-packages/sqlalchemy/orm/context.py", line 306, in orm_execute_statement
    result = conn.execute(
             ^^^^^^^^^^^^^
  File "/home/runner/workspace/.pythonlibs/lib/python3.11/site-packages/sqlalchemy/engine/base.py", line 1419, in execute
    return meth(
           ^^^^^
  File "/home/runner/workspace/.pythonlibs/lib/python3.11/site-packages/sqlalchemy/sql/elements.py", line 526, in _execute_on_connection
    return connection._execute_clauseelement(
           ^^^^^^^^^^^^^^^^^^^^^^^^^^^^^^^^^^
  File "/home/runner/workspace/.pythonlibs/lib/python3.11/site-packages/sqlalchemy/engine/base.py", line 1641, in _execute_clauseelement
    ret = self._execute_context(
          ^^^^^^^^^^^^^^^^^^^^^^
  File "/home/runner/workspace/.pythonlibs/lib/python3.11/site-packages/sqlalchemy/engine/base.py", line 1846, in _execute_context
    return self._exec_single_context(
           ^^^^^^^^^^^^^^^^^^^^^^^^^^
  File "/home/runner/workspace/.pythonlibs/lib/python3.11/site-packages/sqlalchemy/engine/base.py", line 1986, in _exec_single_context
    self._handle_dbapi_exception(
  File "/home/runner/workspace/.pythonlibs/lib/python3.11/site-packages/sqlalchemy/engine/base.py", line 2355, in _handle_dbapi_exception
    raise sqlalchemy_exception.with_traceback(exc_info[2]) from e
  File "/home/runner/workspace/.pythonlibs/lib/python3.11/site-packages/sqlalchemy/engine/base.py", line 1967, in _exec_single_context
    self.dialect.do_execute(
  File "/home/runner/workspace/.pythonlibs/lib/python3.11/site-packages/sqlalchemy/engine/default.py", line 951, in do_execute
    cursor.execute(statement, parameters)
sqlalchemy.exc.ProgrammingError: (psycopg2.errors.UndefinedColumn) column users.grupo_id does not exist
LINE 1: ...sers_nome_completo, users.perfil AS users_perfil, users.grup...
                                                             ^

[SQL: SELECT users.id AS users_id, users.username AS users_username, users.email AS users_email, users.password_hash AS users_password_hash, users.nome_completo AS users_nome_completo, users.perfil AS users_perfil, users.grupo_id AS users_grupo_id, users.cargo AS users_cargo, users.receber_notificacoes AS users_receber_notificacoes, users.ativo AS users_ativo, users.data_criacao AS users_data_criacao, users.ultimo_login AS users_ultimo_login, users.reset_token AS users_reset_token, users.reset_token_expiry AS users_reset_token_expiry 
FROM users 
WHERE users.id = %(pk_1)s]
[parameters: {'pk_1': 1}]
(Background on this error at: https://sqlalche.me/e/20/f405)
2025-09-15 15:34:18 INFO werkzeug: 172.31.82.130 - - [15/Sep/2025 15:34:18] "GET / HTTP/1.1" 500 - [in /home/runner/workspace/.pythonlibs/lib/python3.11/site-packages/werkzeug/_internal.py:97]
